<?xml version="1.0" encoding="utf-8"?>
<!-- This URDF was automatically created by SolidWorks to URDF Exporter! Originally created by Stephen Brawner (brawner@gmail.com) 
     Commit Version: 1.6.0-1-g15f4949  Build Version: 1.6.7594.29634
     For more information, please see http://wiki.ros.org/sw_urdf_exporter -->
<robot
  name="dh_robotics_ag145">
  <link
    name="base_link">
    <inertial>
      <origin
        xyz="4.22096179276271E-09 -8.66337897962713E-05 0.00351545641909857"
        rpy="0 0 0" />
      <mass
        value="0.0244063265095657" />
      <inertia
        ixx="5.17090412144922E-06"
        ixy="2.1574281704417E-13"
        ixz="-1.62385477492139E-13"
        iyy="1.55299243331649E-05"
        iyz="-3.38892310365514E-09"
        izz="2.02963394517234E-05" />
    </inertial>
    <visual>
      <origin
        xyz="0 0 0"
        rpy="0 0 0" />
      <geometry>
        <mesh
          filename="package://dh_robotics_ag145_urdf/meshes/base_link.STL" />
      </geometry>
      <material
        name="">
        <color
          rgba="0.792156862745098 0.819607843137255 0.933333333333333 1" />
      </material>
    </visual>
    <collision>
      <origin
        xyz="0 0 0"
        rpy="0 0 0" />
      <geometry>
        <mesh
          filename="package://dh_robotics_ag145_urdf/meshes/base_link.STL" />
      </geometry>
    </collision>
  </link>
  <link
    name="finger1_knuckle_link">
    <inertial>
      <origin
        xyz="0.019413 1.0484E-09 -0.0013793"
        rpy="0 0 0" />
      <mass
        value="0.0039541" />
      <inertia
        ixx="1.1534E-06"
        ixy="-3.3307E-14"
        ixz="5.4175E-09"
        iyy="6.8389E-07"
        iyz="7.7878E-15"
        izz="1.7667E-06" />
    </inertial>
    <visual>
      <origin
        xyz="0 0 0"
        rpy="0 0 0" />
      <geometry>
        <mesh
          filename="package://dh_robotics_ag145_urdf/meshes/finger1_knuckle_link.STL" />
      </geometry>
      <material
        name="">
        <color
          rgba="0.79216 0.81961 0.93333 1" />
      </material>
    </visual>
    <collision>
      <origin
        xyz="0 0 0"
        rpy="0 0 0" />
      <geometry>
        <mesh
          filename="package://dh_robotics_ag145_urdf/meshes/finger1_knuckle_link.STL" />
      </geometry>
    </collision>
  </link>
  <joint
    name="finger1_joint"
    type="continuous">
    <origin
      xyz="0.016 0 0.10586"
      rpy="0 0 0" />
    <parent
      link="base_link" />
    <child
      link="finger1_knuckle_link" />
    <axis
      xyz="0 1 0" />
    <limit
      lower="0"
      upper="0.6"
      effort="105"
      velocity="10" />
  </joint>
  <link
    name="finger1_finger_link">
    <inertial>
      <origin
        xyz="-0.012522 -9.1789E-09 0.034743"
        rpy="0 0 0" />
      <mass
        value="0.01141" />
      <inertia
        ixx="7.7273E-06"
        ixy="5.2238E-14"
        ixz="2.7021E-06"
        iyy="7.7164E-06"
        iyz="2.4255E-13"
        izz="2.4386E-06" />
    </inertial>
    <visual>
      <origin
        xyz="0 0 0"
        rpy="0 0 0" />
      <geometry>
        <mesh
          filename="package://dh_robotics_ag145_urdf/meshes/finger1_finger_link.STL" />
      </geometry>
      <material
        name="">
        <color
          rgba="0.79216 0.81961 0.93333 1" />
      </material>
    </visual>
    <collision>
      <origin
        xyz="0 0 0"
        rpy="0 0 0" />
      <geometry>
        <mesh
          filename="package://dh_robotics_ag145_urdf/meshes/finger1_finger_link.STL" />
      </geometry>
    </collision>
  </link>
  <joint
    name="finger1_finger_joint"
    type="continuous">
    <origin
      xyz="0.036999 0 -0.00019698"
      rpy="0 0 0" />
    <parent
      link="finger1_knuckle_link" />
    <child
      link="finger1_finger_link" />
    <axis
      xyz="0 1 0" />
    <limit
      lower="0"
      upper="1"
      effort="105"
      velocity="10" />
    <mimic
      joint="finger1_joint"
      multiplier="0.5"
      offset="0" />
  </joint>
  <link
    name="finger1_inner_knuckle_link">
    <inertial>
      <origin
        xyz="-0.0051218 -8.3333E-10 0.038185"
        rpy="0 0 0" />
      <mass
        value="0.017156" />
      <inertia
        ixx="1.5431E-05"
        ixy="3.7731E-14"
        ixz="1.2687E-06"
        iyy="1.2149E-05"
        iyz="-3.4837E-13"
        izz="3.7944E-06" />
    </inertial>
    <visual>
      <origin
        xyz="0 0 0"
        rpy="0 0 0" />
      <geometry>
        <mesh
          filename="package://dh_robotics_ag145_urdf/meshes/finger1_inner_knuckle_link.STL" />
      </geometry>
      <material
        name="">
        <color
          rgba="0.79216 0.81961 0.93333 1" />
      </material>
    </visual>
    <collision>
      <origin
        xyz="0 0 0"
        rpy="0 0 0" />
      <geometry>
        <mesh
          filename="package://dh_robotics_ag145_urdf/meshes/finger1_inner_knuckle_link.STL" />
      </geometry>
    </collision>
  </link>
  <joint
    name="finger1_inner_knuckle_joint"
    type="continuous">
    <origin
      xyz="0.016 0 0.10586"
      rpy="0 0 0" />
    <parent
      link="base_link" />
    <child
      link="finger1_inner_knuckle_link" />
    <axis
      xyz="0 1 0" />
    <limit
      lower="0"
      upper="1"
      effort="105"
      velocity="10" />
    <mimic
      joint="finger1_joint"
      multiplier="1.49"
      offset="0" />
  </joint>
  <link
    name="finger1_finger_tip_link">
    <inertial>
      <origin
        xyz="0.0019731 -1.4867E-09 0.010631"
        rpy="0 0 0" />
      <mass
        value="0.012397" />
      <inertia
        ixx="1.0948E-06"
        ixy="4.5713E-14"
        ixz="1.3947E-07"
        iyy="1.0269E-06"
        iyz="-5.5222E-15"
        izz="8.431E-07" />
    </inertial>
    <visual>
      <origin
        xyz="0 0 0"
        rpy="0 0 0" />
      <geometry>
        <mesh
          filename="package://dh_robotics_ag145_urdf/meshes/finger1_finger_tip_link.STL" />
      </geometry>
      <material
        name="">
        <color
          rgba="0.79216 0.81961 0.93333 1" />
      </material>
    </visual>
    <collision>
      <origin
        xyz="0 0 0"
        rpy="0 0 0" />
      <geometry>
        <mesh
          filename="package://dh_robotics_ag145_urdf/meshes/finger1_finger_tip_link.STL" />
      </geometry>
    </collision>
  </link>
  <joint
    name="finger1_finger_tip_joint"
    type="continuous">
    <origin
      xyz="-0.0081054 0 0.086119"
      rpy="0 0 0" />
    <parent
      link="finger1_inner_knuckle_link" />
    <child
      link="finger1_finger_tip_link" />
    <axis
      xyz="0 -1 0" />
    <limit
      lower="0"
      upper="1"
      effort="105"
      velocity="10" />
    <mimic
      joint="finger1_inner_knuckle_joint"
      multiplier="1"
      offset="0" />
  </joint>
  <link
    name="finger2_knuckle_link">
    <inertial>
      <origin
        xyz="0.019413 0.00025 -0.0013793"
        rpy="0 0 0" />
      <mass
        value="0.0039541" />
      <inertia
        ixx="1.1534E-06"
        ixy="-3.3307E-14"
        ixz="5.4175E-09"
        iyy="6.8389E-07"
        iyz="7.7878E-15"
        izz="1.7667E-06" />
    </inertial>
    <visual>
      <origin
        xyz="0 0 0"
        rpy="0 0 0" />
      <geometry>
        <mesh
          filename="package://dh_robotics_ag145_urdf/meshes/finger2_knuckle_link.STL" />
      </geometry>
      <material
        name="">
        <color
          rgba="0.79216 0.81961 0.93333 1" />
      </material>
    </visual>
    <collision>
      <origin
        xyz="0 0 0"
        rpy="0 0 0" />
      <geometry>
        <mesh
          filename="package://dh_robotics_ag145_urdf/meshes/finger2_knuckle_link.STL" />
      </geometry>
    </collision>
  </link>
  <joint
    name="finger2_joint"
    type="continuous">
    <origin
      xyz="-0.016 0.00025 0.10586"
      rpy="0 0 3.1416" />
    <parent
      link="base_link" />
    <child
      link="finger2_knuckle_link" />
    <axis
      xyz="0 1 0" />
    <limit
      lower="0"
      upper="1"
      effort="105"
      velocity="10" />
    <mimic
      joint="finger1_joint"
      multiplier="1"
      offset="0" />
  </joint>
  <link
    name="finger2_finger_link">
    <inertial>
      <origin
        xyz="-0.012522 -0.00025001 0.034743"
        rpy="0 0 0" />
      <mass
        value="0.01141" />
      <inertia
        ixx="7.7273E-06"
        ixy="5.2238E-14"
        ixz="2.7021E-06"
        iyy="7.7164E-06"
        iyz="2.4255E-13"
        izz="2.4386E-06" />
    </inertial>
    <visual>
      <origin
        xyz="0 0 0"
        rpy="0 0 0" />
      <geometry>
        <mesh
          filename="package://dh_robotics_ag145_urdf/meshes/finger2_finger_link.STL" />
      </geometry>
      <material
        name="">
        <color
          rgba="0.79216 0.81961 0.93333 1" />
      </material>
    </visual>
    <collision>
      <origin
        xyz="0 0 0"
        rpy="0 0 0" />
      <geometry>
        <mesh
          filename="package://dh_robotics_ag145_urdf/meshes/finger2_finger_link.STL" />
      </geometry>
    </collision>
  </link>
  <joint
    name="finger2_finger_joint"
    type="continuous">
    <origin
      xyz="0.036999 0.0005 -0.00019698"
      rpy="0 0 0" />
    <parent
      link="finger2_knuckle_link" />
    <child
      link="finger2_finger_link" />
    <axis
      xyz="0 1 0" />
    <limit
      lower="0"
      upper="1"
      effort="105"
      velocity="10" />
    <mimic
      joint="finger1_finger_joint"
      multiplier="1"
      offset="0" />
  </joint>
  <link
    name="finger2_inner_knuckle_link">
    <inertial>
      <origin
        xyz="0 0 0"
        rpy="0 0 0" />
      <mass
        value="0" />
      <inertia
        ixx="0"
        ixy="0"
        ixz="0"
        iyy="0"
        iyz="0"
        izz="0" />
    </inertial>
    <visual>
      <origin
        xyz="0 0 0"
        rpy="0 0 0" />
      <geometry>
        <mesh
          filename="package://dh_robotics_ag145_urdf/meshes/finger2_inner_knuckle_link.STL" />
      </geometry>
      <material
        name="">
        <color
          rgba="1 1 1 1" />
      </material>
    </visual>
    <collision>
      <origin
        xyz="0 0 0"
        rpy="0 0 0" />
      <geometry>
        <mesh
          filename="package://dh_robotics_ag145_urdf/meshes/finger2_inner_knuckle_link.STL" />
      </geometry>
    </collision>
  </link>
  <joint
    name="finger2_inner_knuckle_joint"
    type="continuous">
    <origin
      xyz="-0.016 0.00025 0.10586"
      rpy="0 0 3.1416" />
    <parent
      link="base_link" />
    <child
      link="finger2_inner_knuckle_link" />
    <axis
      xyz="0 1 0" />
    <limit
      lower="0"
      upper="1"
      effort="105"
      velocity="10" />
    <mimic
      joint="finger1_inner_knuckle_joint"
      multiplier="1"
      offset="0" />
  </joint>
  <link
    name="finger2_finger_tip_link">
    <inertial>
      <origin
        xyz="0.0019731 3.1569E-10 0.010631"
        rpy="0 0 0" />
      <mass
        value="0.012397" />
      <inertia
        ixx="1.0948E-06"
        ixy="-9.4676E-15"
        ixz="1.3947E-07"
        iyy="1.0269E-06"
        iyz="1.771E-14"
        izz="8.431E-07" />
    </inertial>
    <visual>
      <origin
        xyz="0 0 0"
        rpy="0 0 0" />
      <geometry>
        <mesh
          filename="package://dh_robotics_ag145_urdf/meshes/finger2_finger_tip_link.STL" />
      </geometry>
      <material
        name="">
        <color
          rgba="0.79216 0.81961 0.93333 1" />
      </material>
    </visual>
    <collision>
      <origin
        xyz="0 0 0"
        rpy="0 0 0" />
      <geometry>
        <mesh
          filename="package://dh_robotics_ag145_urdf/meshes/finger2_finger_tip_link.STL" />
      </geometry>
    </collision>
  </link>
  <joint
    name="finger2_finger_tip_joint"
    type="continuous">
    <origin
      xyz="-0.0081054 0.00025 0.086119"
      rpy="0 0 0" />
    <parent
      link="finger2_inner_knuckle_link" />
    <child
      link="finger2_finger_tip_link" />
    <axis
      xyz="0 -1 0" />
    <limit
      lower="0"
      upper="1"
      effort="105"
      velocity="10" />
    <mimic
      joint="finger1_finger_tip_joint"
      multiplier="1"
      offset="0" />
  </joint>
</robot>
